Workbook

Sheet предлог_с
A1: Корпус | B1: utterance_id | C1: From | D1: To | E1: File | F1: Id | G1: String id | H1: Gender | I1: Year of birth | J1: Education | K1: Place of birth | L1: Place of living | M1: Left Context | N1: DMatch | O1: Right Context | P1: имя в предложной группе | Q1: Топоним | R1: деревня, город, область, страна и пр. | S1: жилище | T1: природные пространственные локации | U1: учреждения | V1: пространственные локации | W1: остальные употребления | X1: выход из контейнера | Y1: материал | Z1: армия, тюрьма, служба, фазы жизни | AA1: коллектив, группа | AB1: деньги, заработок, зарплата | AC1: Прайминг | AD1: пространственная/объектная/определительная | AE1: глагольная/именная | AF1: соответствует/не соответствует литературной норме
A2: Корпус говора деревни Пятиусово | B2: 49 | C2: 1082342 | D2: 1089680 | E2: 20231028zes1942 | M2: У нас э... А | N2: с | O2: другой деревни и шла старушка, ну она моложе меня (мене) было, ей побольше, семьдесят... | P2: деревня | Q2: 0 | R2: 1 | S2: 0 | T2: 0 | U2: 0 | V2: 0 | W2: 0 | X2: 0 | Y2: 0 | Z2: 0 | AA2: 0 | AB2: 0 | AC2: 0 | AD2: s | AE2: v | AF2: n
A3: Корпус говора деревни Пятиусово | B3: 110 | C3: 1383096 | D3: 1384946 | E3: 20231028zes1942 | M3: А вы это, не | N3: с | O3: Макеева, детка? | P3: Макеево | Q3: 1 | R3: 0 | S3: 0 | T3: 0 | U3: 0 | V3: 0 | W3: 0 | X3: 0 | Y3: 0 | Z3: 0 | AA3: 0 | AB3: 0 | AC3: 0 | AD3: a | AE3: n | AF3: n
A4: Корпус говора деревни Пятиусово | B4: 112 | C4: 1390055 | D4: 1394577 | E4: 20231028zes1942 | N4: С | O4: Макеева похожа... Там, при этом... У нас приехадчи была семья, девять детей... | P4: Макеево | Q4: 1 | R4: 0 | S4: 0 | T4: 0 | U4: 0 | V4: 0 | W4: 0 | X4: 0 | Y4: 0 | Z4: 0 | AA4: 0 | AB4: 0 | AC4: 0 | AD4: a | AE4: n | AF4: n
A5: Корпус говора деревни Пятиусово | B5: 115 | C5: 1407389 | D5: 1411911 | E5: 20231028zes1942 | M5: Она таджи = | N5: с | O5: Таджикистана... Есть такая? Государство... | P5: Таджикистан | Q5: 1 | R5: 0 | S5: 0 | T5: 0 | U5: 0 | V5: 0 | W5: 0 | X5: 0 | Y5: 0 | Z5: 0 | AA5: 0 | AB5: 0 | AC5: 0 | AD5: a | AE5: n | AF5: n
A6: Корпус говора деревни Пятиусово | B6: 135 | C6: 1495040 | D6: 1499314 | E6: 20231028zes1942 | M6: А морозы начнутся, | N6: с | O6: дому не выходили никуда, так что вот... | P6: дом | Q6: 0 | R6: 0 | S6: 1 | T6: 0 | U6: 0 | V6: 0 | W6: 0 | X6: 0 | Y6: 0 | Z6: 0 | AA6: 0 | AB6: 0 | AC6: 0 | AD6: s | AE6: v | AF6: n
A7: Корпус говора деревни Пятиусово | B7: 142 | C7: 1530129 | D7: 1537572 | E7: 20231028zes1942 | M7: Но так как у нас | N7: с | O7: деревни не было этих, вальщиков, то... Мы не возили... И родители тогда... | P7: деревня | Q7: 0 | R7: 1 | S7: 0 | T7: 0 | U7: 0 | V7: 0 | W7: 0 | X7: 0 | Y7: 0 | Z7: 0 | AA7: 0 | AB7: 0 | AC7: 0 | AD7: a | AE7: n | AF7: n
A8: Корпус говора деревни Пятиусово | B8: 188 | C8: 1850333 | D8: 1855840 | E8: 20231028zes1942 | M8: Ездил надзиратель, который выкидывал эту картошку | N8: с | O8: вёдер, если он… Если он захватит (захватить). | P8: ведра | Q8: 0 | R8: 0 | S8: 0 | T8: 0 | U8: 0 | V8: 0 | W8: 0 | X8: 1 | Y8: 0 | Z8: 0 | AA8: 0 | AB8: 0 | AC8: 0 | AD8: s | AE8: v | AF8: n
A9: Корпус говора деревни Пятиусово | B9: 206 | C9: 1953370 | D9: 1961300 | E9: 20231028zes1942 | M9: И мать привезла два мешка картошки | N9: с | O9: Антонова. Там пески, а у нас, такая, суглинистая. | P9: Антоново | Q9: 1 | R9: 0 | S9: 0 | T9: 0 | U9: 0 | V9: 0 | W9: 0 | X9: 0 | Y9: 0 | Z9: 0 | AA9: 0 | AB9: 0 | AC9: 0 | AD9: s | AE9: v | AF9: n
A10: Корпус говора деревни Пятиусово | B10: 328 | C10: 516610 | D10: 524930 | E10: 20240729evm1937 | G10: EVM1937 | I10: 1937 | J10: техникум | K10: Коковино | L10: Пятиусово | M10: Ехали нас человек пятнадцать или семнадцать отсюда, | N10: с | O10: Западной Двины в Тверь. | P10: Западная Двина | Q10: 1 | R10: 0 | S10: 0 | T10: 0 | U10: 0 | V10: 0 | W10: 0 | X10: 0 | Y10: 0 | Z10: 0 | AA10: 0 | AB10: 0 | AC10: 0 | AD10: s | AE10: v | AF10: n
A11: Корпус говора деревни Пятиусово | B11: 376 | C11: 802725 | D11: 813830 | E11: 20240729evm1937 | G11: EVM1937 | I11: 1937 | J11: техникум | K11: Коковино | L11: Пятиусово | M11: Я спускал оттуда станцию, | N11: с | O11: Бакуриани, с тягачом АТС, а сзади приёмо - передающая кабина, 20 тонн. | P11: Бакуриани | Q11: 1 | R11: 0 | S11: 0 | T11: 0 | U11: 0 | V11: 0 | W11: 0 | X11: 0 | Y11: 0 | Z11: 0 | AA11: 0 | AB11: 0 | AC11: 0 | AD11: s | AE11: v | AF11: n
A12: Корпус говора деревни Пятиусово | B12: 382 | C12: 851500 | D12: 855750 | E12: 20240729evm1937 | G12: EVM1937 | I12: 1937 | J12: техникум | K12: Коковино | L12: Пятиусово | M12: Вот оттуда эту станцию спускал | N12: с | O12: этой Бакуриани. | P12: Бакуриани | Q12: 1 | R12: 0 | S12: 0 | T12: 0 | U12: 0 | V12: 0 | W12: 0 | X12: 0 | Y12: 0 | Z12: 0 | AA12: 0 | AB12: 0 | AC12: 0 | AD12: s | AE12: v | AF12: n
A13: Корпус говора деревни Пятиусово | B13: 405 | C13: 1004680 | D13: 1014830 | E13: 20240729evm1937 | G13: EVM1937 | I13: 1937 | J13: техникум | K13: Коковино | L13: Пятиусово | M13: Они не едут этим (этом) кругом, они подъехали трактор опустили, сам из ( | N13: с | O13: ) трактора выскочил, и трактор туда до низу и добежал. | P13: трактор | Q13: 0 | R13: 0 | S13: 0 | T13: 0 | U13: 0 | V13: 0 | W13: 0 | X13: 1 | Y13: 0 | Z13: 0 | AA13: 0 | AB13: 0 | AC13: 0 | AD13: s | AE13: v | AF13: n
A14: Корпус говора деревни Пятиусово | B14: 445 | C14: 1200212 | D14: 1205425 | E14: 20240729evm1937 | G14: EVM1937 | I14: 1937 | J14: техникум | K14: Коковино | L14: Пятиусово | M14: Нас там обучилось | N14: с | O14: Западной Двины человек двенадцать. | P14: Западная Двина | Q14: 1 | R14: 0 | S14: 0 | T14: 0 | U14: 0 | V14: 0 | W14: 0 | X14: 0 | Y14: 0 | Z14: 0 | AA14: 0 | AB14: 0 | AC14: 0 | AD14: a | AE14: n | AF14: n
A15: Корпус говора деревни Пятиусово | B15: 620 | C15: 2148950 | D15: 2152260 | E15: 20240729evm1937 | G15: EVM1937 | I15: 1937 | J15: техникум | K15: Коковино | L15: Пятиусово | M15: Из ( | N15: с | O15: ) Каськово пришли? А ну Каськово вы знаете, вы в Каськово... | P15: Каськово | Q15: 1 | R15: 0 | S15: 0 | T15: 0 | U15: 0 | V15: 0 | W15: 0 | X15: 0 | Y15: 0 | Z15: 0 | AA15: 0 | AB15: 0 | AC15: 0 | AD15: s | AE15: v | AF15: n
A16: Корпус говора деревни Пятиусово | B16: 662 | C16: 2314500 | D16: 2318730 | E16: 20240729evm1937 | G16: EVM1937 | I16: 1937 | J16: техникум | K16: Коковино | L16: Пятиусово | M16: У меня товарищ бывало приезжал | N16: с | O16: Треста, с Калинина в гости. | P16: Треста | Q16: 1 | R16: 0 | S16: 0 | T16: 0 | U16: 0 | V16: 0 | W16: 0 | X16: 0 | Y16: 0 | Z16: 0 | AA16: 0 | AB16: 0 | AC16: 0 | AD16: s | AE16: v | AF16: n
A17: Корпус говора деревни Пятиусово | B17: 662 | C17: 2314500 | D17: 2318730 | E17: 20240729evm1937 | G17: EVM1937 | I17: 1937 | J17: техникум | K17: Коковино | L17: Пятиусово | M17: У меня товарищ бывало приезжал с Треста, | N17: с | O17: Калинина в гости. | P17: Калинина | Q17: 1 | R17: 0 | S17: 0 | T17: 0 | U17: 0 | V17: 0 | W17: 0 | X17: 0 | Y17: 0 | Z17: 0 | AA17: 0 | AB17: 0 | AC17: 0 | AD17: s | AE17: v | AF17: n
A18: Корпус говора деревни Пятиусово | B18: 716 | C18: 2686180 | D18: 2688610 | E18: 20240729evm1937 | G18: EVM1937 | I18: 1937 | J18: техникум | K18: Коковино | L18: Пятиусово | M18: И | N18: со | O18: со льна сделали с этого волокно. | P18: лен | Q18: 0 | R18: 0 | S18: 0 | T18: 0 | U18: 0 | V18: 0 | W18: 0 | X18: 0 | Y18: 1 | Z18: 0 | AA18: 0 | AB18: 0 | AC18: 0 | AD18: o | AE18: v | AF18: n
A19: Корпус говора деревни Пятиусово | B19: 718 | C19: 2693990 | D19: 2698740 | E19: 20240729evm1937 | G19: EVM1937 | I19: 1937 | J19: техникум | K19: Коковино | L19: Пятиусово | M19: И | N19: с | O19: этого материала шили брюки, кафтан. | P19: материал | Q19: 0 | R19: 0 | S19: 0 | T19: 0 | U19: 0 | V19: 0 | W19: 0 | X19: 0 | Y19: 1 | Z19: 0 | AA19: 0 | AB19: 0 | AC19: 0 | AD19: o | AE19: v | AF19: n
A20: Корпус говора деревни Пятиусово | B20: 743 | C20: 2802927 | D20: 2809144 | E20: 20240729evm1937 | G20: EVM1937 | I20: 1937 | J20: техникум | K20: Коковино | L20: Пятиусово | M20: Она строилась так, чтобы со всех деревень, | N20: с | O20: округи, был доступ одинаков. | P20: округи | Q20: 0 | R20: 1 | S20: 0 | T20: 0 | U20: 0 | V20: 0 | W20: 0 | X20: 0 | Y20: 0 | Z20: 0 | AA20: 0 | AB20: 0 | AC20: 0 | AD20: a | AE20: n | AF20: n
A21: Корпус говора деревни Пятиусово | B21: 764 | C21: 2909762 | D21: 2912855 | E21: 20240729evm1937 | G21: EVM1937 | I21: 1937 | J21: техникум | K21: Коковино | L21: Пятиусово | M21: Мужики приходят | N21: с | O21: деревень, которые пять - шесть киллометров. | P21: деревни | Q21: 0 | R21: 1 | S21: 0 | T21: 0 | U21: 0 | V21: 0 | W21: 0 | X21: 0 | Y21: 0 | Z21: 0 | AA21: 0 | AB21: 0 | AC21: 0 | AD21: s | AE21: v | AF21: n
... A42: Корпус говора деревни Пятиусово | B42: 1361 | C42: 1611447 | D42: 1631875 | E42: 20231023pvv1935 | G42: PVV1935 | I42: 1935 | J42: техникум | K42: Пятиусово | L42: Пятиусово | M42: И это... Посадить... То есть принесла | N42: с | O42: почты севок этом мне (мене). Ну и грядку помогла мне... Было земля под осень сделанная... Посадили, я её (ее) потихонечку пропалывал, лук поливал, чеснок не поливал. | P42: почта | Q42: 0 | R42: 0 | S42: 0 | T42: 0 | U42: 1 | V42: 0 | W42: 0 | X42: 0 | Y42: 0 | Z42: 0 | AA42: 0 | AB42: 0 | AC42: 0 | AD42: s | AE42: v | AF42: y
A43: Корпус говора деревни Пятиусово | B43: 1462 | C43: 53840 | D43: 57140 | E43: 20240728zes1942 | M43: А сейчас вроде бы дочка приехадчи, из ( | N43: с | O43: ) Ленинграда приехала. | P43: Ленинграда | Q43: 1 | R43: 0 | S43: 0 | T43: 0 | U43: 0 | V43: 0 | W43: 0 | X43: 0 | Y43: 0 | Z43: 0 | AA43: 0 | AB43: 0 | AC43: 0 | AD43: s | AE43: v | AF43: n
A44: Корпус говора деревни Пятиусово | B44: 1463 | C44: 57480 | D44: 65630 | E44: 20240728zes1942 | M44: Она живёт в своём доме. Это как и = с = из ( | N44: с | O44: ) Каськово идёте прямо, так сразу первый дом, а на правую руку голубой. | P44: Каськово | Q44: 1 | R44: 0 | S44: 0 | T44: 0 | U44: 0 | V44: 0 | W44: 0 | X44: 0 | Y44: 0 | Z44: 0 | AA44: 0 | AB44: 0 | AC44: 0 | AD44: s | AE44: v | AF44: n
A45: Корпус говора деревни Пятиусово | B45: 1464 | C45: 67240 | D45: 73340 | E45: 20240728zes1942 | M45: Да, сразу как | N45: с | O45: Каськова вышли, с Пахнова вышли, к нам идёте уже, уже Пятиусово вы пришли. | P45: Каськова | Q45: 1 | R45: 0 | S45: 0 | T45: 0 | U45: 0 | V45: 0 | W45: 0 | X45: 0 | Y45: 0 | Z45: 0 | AA45: 0 | AB45: 0 | AC45: 0 | AD45: s | AE45: v | AF45: n
A46: Корпус говора деревни Пятиусово | B46: 1464 | C46: 67240 | D46: 73340 | E46: 20240728zes1942 | M46: Да, сразу как с Каськова вышли, | N46: с | O46: Пахнова вышли, к нам идёте уже, уже Пятиусово вы пришли. | P46: Пахнова | Q46: 1 | R46: 0 | S46: 0 | T46: 0 | U46: 0 | V46: 0 | W46: 0 | X46: 0 | Y46: 0 | Z46: 0 | AA46: 0 | AB46: 0 | AC46: 0 | AD46: s | AE46: v | AF46: n
A47: Корпус говора деревни Пятиусово | B47: 1465 | C47: 73580 | D47: 81840 | E47: 20240728zes1942 | M47: Сразу этот дом направо первый, если | N47: с | O47: Каськова идти. А если... А если от нас вы пойдёте, то на левую руку последний. | P47: Каськова | Q47: 1 | R47: 0 | S47: 0 | T47: 0 | U47: 0 | V47: 0 | W47: 0 | X47: 0 | Y47: 0 | Z47: 0 | AA47: 0 | AB47: 0 | AC47: 0 | AD47: s | AE47: v | AF47: n
A48: Корпус говора деревни Пятиусово | B48: 1572 | C48: 562070 | D48: 567890 | E48: 20240728zes1942 | M48: Туда делали лепёшки | N48: с | O48: гли =. Ну, детская игра, туда ставили. Вот такая игра была. Больше ничего. | P48: глины | Q48: 0 | R48: 0 | S48: 0 | T48: 0 | U48: 0 | V48: 0 | W48: 0 | X48: 0 | Y48: 1 | Z48: 0 | AA48: 0 | AB48: 0 | AC48: 0 | AD48: o | AE48: v | AF48: n
A49: Корпус говора деревни Пятиусово | B49: 1615 | C49: 773280 | D49: 778770 | E49: 20240728zes1942 | M49: А потом вот в Даниловское. Это надо было идти из ( | N49: с | O49: ) Пятиусова два километра или три. | P49: Пятиусова | Q49: 1 | R49: 0 | S49: 0 | T49: 0 | U49: 0 | V49: 0 | W49: 0 | X49: 0 | Y49: 0 | Z49: 0 | AA49: 0 | AB49: 0 | AC49: 0 | AD49: s | AE49: v | AF49: n
A50: Корпус говора деревни Пятиусово | B50: 1711 | C50: 1255100 | D50: 1260000 | E50: 20240728zes1942 | M50: А так как она ездила на лошадях, она всегда из ( | N50: с | O50: ) Пятиусово что - то приве = привезёт. | P50: Пятиусово | Q50: 1 | R50: 0 | S50: 0 | T50: 0 | U50: 0 | V50: 0 | W50: 0 | X50: 0 | Y50: 0 | Z50: 0 | AA50: 0 | AB50: 0 | AC50: 0 | AD50: s | AE50: v | AF50: n
A51: Корпус говора деревни Пятиусово | B51: 2034 | C51: 2709900 | D51: 2713880 | E51: 20240728zes1942 | M51: Он был, я скажу: как | N51: с | O51: Торопы (Торопи) едите, так сразу. | P51: Торопы | Q51: 1 | R51: 0 | S51: 0 | T51: 0 | U51: 0 | V51: 0 | W51: 0 | X51: 0 | Y51: 0 | Z51: 0 | AA51: 0 | AB51: 0 | AC51: 0 | AD51: s | AE51: v | AF51: n
A52: Корпус говора деревни Пятиусово | B52: 2051 | C52: 2770090 | D52: 2775070 | E52: 20240728zes1942 | M52: Тоже как выезжаешь из ( | N52: с | O52: ) Торопы (Торопи) в низине (низина) дом стоит в низине (низина), красная крыша, по - моему, и там что - то ещё. | P52: Торопы | Q52: 1 | R52: 0 | S52: 0 | T52: 0 | U52: 0 | V52: 0 | W52: 0 | X52: 0 | Y52: 0 | Z52: 0 | AA52: 0 | AB52: 0 | AC52: 0 | AD52: s | AE52: v | AF52: n
A53: Корпус говора деревни Пятиусово | B53: 2099 | C53: 2944800 | D53: 2948090 | E53: 20240728zes1942 | M53: Сейчас скажу кто учился, | N53: с | O53: каких деревень. Так. | P53: деревень | Q53: 0 | R53: 1 | S53: 0 | T53: 0 | U53: 0 | V53: 0 | W53: 0 | X53: 0 | Y53: 0 | Z53: 0 | AA53: 0 | AB53: 0 | AC53: 0 | AD53: a | AE53: n | AF53: n
A54: Корпус говора деревни Пятиусово | B54: 2129 | C54: 3033810 | D54: 3039380 | E54: 20240728zes1942 | M54: И тогда вот дочка моя уже ходила из ( | N54: с | O54: ) Каськово, ходила в Пятиусововот в эту шк =. | P54: Каськово | Q54: 1 | R54: 0 | S54: 0 | T54: 0 | U54: 0 | V54: 0 | W54: 0 | X54: 0 | Y54: 0 | Z54: 0 | AA54: 0 | AB54: 0 | AC54: 0 | AD54: s | AE54: v | AF54: n
... A76: Корпус говора деревни Пятиусово | B76: 3889 | C76: 1511350 | D76: 1514520 | E76: 20240802zes1942 | M76: Они сами от нас, так, | N76: с | O76: Каськова. Они жили... | P76: Каськова | Q76: 1 | R76: 0 | S76: 0 | T76: 0 | U76: 0 | V76: 0 | W76: 0 | X76: 0 | Y76: 0 | Z76: 0 | AA76: 0 | AB76: 0 | AC76: 0 | AD76: a | AE76: n | AF76: n
A77: Корпус говора деревни Пятиусово | B77: 4057 | C77: 2096660 | D77: 2099150 | E77: 20240802zes1942 | N77: С | O77: Горькова? Ну вот где - то туда, где - то в хозяйства туда. | P77: Горькова | Q77: 1 | R77: 0 | S77: 0 | T77: 0 | U77: 0 | V77: 0 | W77: 0 | X77: 0 | Y77: 0 | Z77: 0 | AA77: 0 | AB77: 0 | AC77: 0 | AD77: a | AE77: n | AF77: n
A78: Корпус говора деревни Пятиусово | B78: 4134 | C78: 2333610 | D78: 2339270 | E78: 20240802zes1942 | M78: Ты, говорю, видишь? Если сверху смотреть | N78: с | O78: самолёта, то я живу в кругу борщевика. | P78: самолёта | Q78: 0 | R78: 0 | S78: 0 | T78: 0 | U78: 0 | V78: 0 | W78: 0 | X78: 1 | Y78: 0 | Z78: 0 | AA78: 0 | AB78: 0 | AC78: 0 | AD78: s | AE78: v | AF78: n
A79: Корпус говора деревни Пятиусово | B79: 4235 | C79: 2657390 | D79: 2659770 | E79: 20240802zes1942 | M79: А в = выключите | N79: с | O79: розетки! | P79: розетки | Q79: 0 | R79: 0 | S79: 0 | T79: 0 | U79: 0 | V79: 0 | W79: 0 | X79: 1 | Y79: 0 | Z79: 0 | AA79: 0 | AB79: 0 | AC79: 0 | AD79: s | AE79: v | AF79: n
A80: Корпус говора деревни Пятиусово | B80: 4408 | C80: 3175420 | D80: 3184220 | E80: 20240802zes1942 | M80: И у нас печа была большая. Я даже не знаю из (с) чего она. Мать сказала, из ( | N80: с | O80: ) камней, вроде, сделана была эта. Она сделана ещё до = до войны. | P80: камней | Q80: 0 | R80: 0 | S80: 0 | T80: 0 | U80: 0 | V80: 0 | W80: 0 | X80: 0 | Y80: 1 | Z80: 0 | AA80: 0 | AB80: 0 | AC80: 0 | AD80: o | AE80: v | AF80: n
A81: Корпус говора деревни Пятиусово | B81: 4410 | C81: 3185030 | D81: 3186490 | E81: 20240802zes1942 | N81: С | O81: хутора перевезена. | P81: хутора | Q81: 0 | R81: 0 | S81: 1 | T81: 0 | U81: 0 | V81: 0 | W81: 0 | X81: 0 | Y81: 0 | Z81: 0 | AA81: 0 | AB81: 0 | AC81: 0 | AD81: s | AE81: v | AF81: n
...

Sheet предлог_из
A1: Корпус | B1: utterance_id | C1: From | D1: To | E1: File | F1: Id | G1: String id | H1: Gender | I1: Year of birth | J1: Education | K1: Place of birth | L1: Place of living | M1: Left Context | N1: DMatch | O1: Right Context | P1: имя в предложной группе | Q1: Топоним | R1: деревня, город, область, страна и пр. | S1: жилище | T1: природные пространственные локации | U1: учреждения | V1: пространственные локации | W1: остальные употребления | X1: выход из контейнера | Y1: материал | Z1: армия, тюрьма, школа, детский сад, институт , универ, служба(?) фазы жизни | AA1: коллектив, группа | AB1: деньги, заработок, зарплата | AC1: Прайминг | AD1: пространственная/объектная/определительная | AE1: глагольная/именная | AF1: соответствует/не соответствует литературной норме
A2: корпус говора деревни Пятиусово | B2: 329 | C2: 525500 | D2: 529400 | E2: 20240729evm1937 | G2: EVM1937 | I2: 1937 | J2: техникум | K2: Коковино | L2: Пятиусово | N2: Из | O2: Твери там эшелон нас вёз, полный состав. | P2: Твери | Q2: 1 | R2: 0 | S2: 0 | T2: 0 | U2: 0 | V2: 0 | W2: 0 | X2: 0 | Y2: 0 | Z2: 0 | AA2: 0 | AB2: 0 | AC2: 0 | AD2: s | AE2: v | AF2: y
A3: корпус говора деревни Пятиусово | B3: 618 | C3: 2143520 | D3: 2145180 | E3: 20240729evm1937 | G3: EVM1937 | I3: 1937 | J3: техникум | K3: Коковино | L3: Пятиусово | N3: Из | O3: Торопы пешком пришли? | P3: Торопы | Q3: 1 | R3: 0 | S3: 0 | T3: 0 | U3: 0 | V3: 0 | W3: 0 | X3: 0 | Y3: 0 | Z3: 0 | AA3: 0 | AB3: 0 | AC3: 0 | AD3: s | AE3: v | AF3: y
A4: корпус говора деревни Пятиусово | B4: 732 | C4: 2758059 | D4: 2762881 | E4: 20240729evm1937 | G4: EVM1937 | I4: 1937 | J4: техникум | K4: Коковино | L4: Пятиусово | M4: Варежки все вязали шерстяные, | N4: из | O4: овец = из овечей шерсти. | P4: овец (овечей шерсти) | Q4: 0 | R4: 0 | S4: 0 | T4: 0 | U4: 0 | V4: 0 | W4: 0 | X4: 0 | Y4: 1 | Z4: 0 | AA4: 0 | AB4: 0 | AC4: 0 | AD4: o | AE4: v | AF4: y
A5: корпус говора деревни Пятиусово | B5: 801 | C5: 3054494 | D5: 3058020 | E5: 20240729evm1937 | G5: EVM1937 | I5: 1937 | J5: техникум | K5: Коковино | L5: Пятиусово | M5: Так говорят, | N5: из | O5: поля в поле два раза ходит. | P5: поля | Q5: 0 | R5: 0 | S5: 0 | T5: 1 | U5: 0 | V5: 0 | W5: 0 | X5: 0 | Y5: 0 | Z5: 0 | AA5: 0 | AB5: 0 | AC5: 0 | AD5: s | AE5: v | AF5: y
A6: корпус говора деревни Пятиусово | B6: 822 | C6: 3133206 | D6: 3138618 | E6: 20240729evm1937 | G6: EVM1937 | I6: 1937 | J6: техникум | K6: Коковино | L6: Пятиусово | N6: Из | O6: этого волокна потом пряли, из этого льна. | P6: волокна | Q6: 0 | R6: 0 | S6: 0 | T6: 0 | U6: 0 | V6: 0 | W6: 0 | X6: 0 | Y6: 1 | Z6: 0 | AA6: 0 | AB6: 0 | AC6: 0 | AD6: o | AE6: v | AF6: y
A7: корпус говора деревни Пятиусово | B7: 822 | C7: 3133206 | D7: 3138618 | E7: 20240729evm1937 | G7: EVM1937 | I7: 1937 | J7: техникум | K7: Коковино | L7: Пятиусово | M7: Из этого волокна потом пряли, | N7: из | O7: этого льна. | P7: льна | Q7: 0 | R7: 0 | S7: 0 | T7: 0 | U7: 0 | V7: 0 | W7: 0 | X7: 0 | Y7: 1 | Z7: 0 | AA7: 0 | AB7: 0 | AC7: 0 | AD7: o | AE7: v | AF7: y
A8: корпус говора деревни Пятиусово | B8: 930 | C8: 47119 | D8: 53919 | E8: 20231026lng1954 | G8: LNG1954 | I8: 1954 | J8: среднее (10 классов) | K8: Пятиусово | L8: Пятиусово | M8: Ну может на этой основе я | N8: из | O8: своего жизненного опыта взял, что восемьдесят процентов женщин они фригидные. | P8: жизненного опыта | Q8: 0 | R8: 0 | S8: 0 | T8: 0 | U8: 0 | V8: 0 | W8: 1 | X8: 0 | Y8: 0 | Z8: 0 | AA8: 0 | AB8: 0 | AC8: 0 | AD8: o | AE8: v | AF8: y
A9: корпус говора деревни Пятиусово | B9: 1017 | C9: 636012 | D9: 640652 | E9: 20231026lng1954 | G9: LNG1954 | I9: 1954 | J9: среднее (10 классов) | K9: Пятиусово | L9: Пятиусово | M9: Я и = т = | N9: из | O9: породы таких людей: дал слово - - я его сдержу. | P9: порода | Q9: 0 | R9: 0 | S9: 0 | T9: 0 | U9: 0 | V9: 0 | W9: 0 | X9: 0 | Y9: 0 | Z9: 0 | AA9: 1 | AB9: 0 | AC9: 0 | AD9: a | AE9: n | AF9: y
A10: корпус говора деревни Пятиусово | B10: 1199 | C10: 68627 | D10: 72812 | E10: 20231023pvv1935 | G10: PVV1935 | I10: 1935 | J10: техникум | K10: Пятиусово | L10: Пятиусово | M10: Ну вот и поменьше народу теперь | N10: из | O10: местных. | P10: местных | Q10: 0 | R10: 0 | S10: 0 | T10: 0 | U10: 0 | V10: 0 | W10: 0 | X10: 0 | Y10: 0 | Z10: 0 | AA10: 1 | AB10: 0 | AC10: 0 | AD10: a | AE10: n | AF10: y
A11: корпус говора деревни Пятиусово | B11: 1417 | C11: 1998214 | D11: 2006294 | E11: 20231023pvv1935 | G11: PVV1935 | I11: 1935 | J11: техникум | K11: Пятиусово | L11: Пятиусово | M11: Сразу поехал в Торопу – там весной уже привозят, это, | N11: из | O11: питомника саженцы – купил пять яблонь. | P11: питомник | Q11: 0 | R11: 0 | S11: 0 | T11: 0 | U11: 1 | V11: 0 | W11: 0 | X11: 0 | Y11: 0 | Z11: 0 | AA11: 0 | AB11: 0 | AC11: 0 | AD11: s | AE11: v | AF11: y
A12: корпус говора деревни Пятиусово | B12: 1647 | C12: 939680 | D12: 942160 | E12: 20240728zes1942 | N12: Из | O12: шести сыновей все были на войне (войны). | P12: сыновья | Q12: 0 | R12: 0 | S12: 0 | T12: 0 | U12: 0 | V12: 0 | W12: 0 | X12: 0 | Y12: 0 | Z12: 0 | AA12: 1 | AB12: 0 | AC12: 0 | AD12: o | AE12: n | AF12: y
A13: корпус говора деревни Пятиусово | B13: 1673 | C13: 1071510 | D13: 1077040 | E13: 20240728zes1942 | M13: Ну у нас все | N13: из | O13: родителей... Мы из детей все живы были. | P13: родители | Q13: 0 | R13: 0 | S13: 0 | T13: 0 | U13: 0 | V13: 0 | W13: 0 | X13: 0 | Y13: 0 | Z13: 0 | AA13: 1 | AB13: 0 | AC13: 0 | AD13: a | AE13: n | AF13: n
A14: корпус говора деревни Пятиусово | B14: 1673 | C14: 1071510 | D14: 1077040 | E14: 20240728zes1942 | M14: Ну у нас все из родителей... Мы | N14: из | O14: детей все живы были. | P14: дети | Q14: 0 | R14: 0 | S14: 0 | T14: 0 | U14: 0 | V14: 0 | W14: 0 | X14: 0 | Y14: 0 | Z14: 0 | AA14: 1 | AB14: 0 | AC14: 0 | AD14: a | AE14: n | AF14: n
A15: корпус говора деревни Пятиусово | B15: 1755 | C15: 1478630 | D15: 1484530 | E15: 20240728zes1942 | M15: Раньше специально носили, | N15: из | O15: Бенец были, был дед и баба. | P15: Бенец | Q15: 1 | R15: 0 | S15: 0 | T15: 0 | U15: 0 | V15: 0 | W15: 0 | X15: 0 | Y15: 0 | Z15: 0 | AA15: 0 | AB15: 0 | AC15: 0 | AD15: a | AE15: n | AF15: y
A16: корпус говора деревни Пятиусово | B16: 2004 | C16: 2564470 | D16: 2568880 | E16: 20240728zes1942 | M16: Ну кор = | N16: из | O16: кормовых для коров сажали брюкву. | P16: кормовые | Q16: 0 | R16: 0 | S16: 0 | T16: 0 | U16: 0 | V16: 0 | W16: 0 | X16: 0 | Y16: 0 | Z16: 0 | AA16: 1 | AB16: 0 | AC16: 0 | AD16: o | AE16: v | AF16: y
A17: корпус говора деревни Пятиусово | B17: 2373 | C17: 4066084 | D17: 4072863 | E17: 20240728zes1942 | M17: В деревне нету никого теперь и = | N17: из | O17: жителей оставши. Сколько жили там - вот одна я оставши теперь, нет никого. | P17: жителей | Q17: 0 | R17: 0 | S17: 0 | T17: 0 | U17: 0 | V17: 0 | W17: 0 | X17: 0 | Y17: 0 | Z17: 0 | AA17: 1 | AB17: 0 | AC17: 0 | AD17: o | AE17: n | AF17: y
A18: корпус говора деревни Пятиусово | B18: 2377 | C18: 4090069 | D18: 4093879 | E18: 20240728zes1942 | M18: И они вот переехали из = | N18: из | O18: этих домов в один из них. | P18: домов | Q18: 0 | R18: 0 | S18: 1 | T18: 0 | U18: 0 | V18: 0 | W18: 0 | X18: 0 | Y18: 0 | Z18: 0 | AA18: 0 | AB18: 0 | AC18: 0 | AD18: s | AE18: v | AF18: y
A19: корпус говора деревни Пятиусово | B19: 2496 | C19: 343620 | D19: 351360 | E19: 20240727zes1942 | M19: Да, теперь вы не узнаешь никого | N19: из | O19: ребят, все взрослые. Где узнаешь, а я уже старая и слепая, зрение плохое у () меня (мне), я плохо вижу. | P19: ребят | Q19: 0 | R19: 0 | S19: 0 | T19: 0 | U19: 0 | V19: 0 | W19: 0 | X19: 0 | Y19: 0 | Z19: 0 | AA19: 1 | AB19: 0 | AC19: 0 | AD19: o | AE19: v | AF19: y
A20: корпус говора деревни Пятиусово | B20: 2788 | C20: 1590666 | D20: 1597152 | E20: 20240727zes1942 | M20: Мои родители, у него (его) отца нету, мать была, мать, по - моему, ещё кто - то был | N20: из | O20: родственников. | P20: родственников | Q20: 0 | R20: 0 | S20: 0 | T20: 0 | U20: 0 | V20: 0 | W20: 0 | X20: 0 | Y20: 0 | Z20: 0 | AA20: 1 | AB20: 0 | AC20: 0 | AD20: a | AE20: n | AF20: y
A21: корпус говора деревни Пятиусово | B21: 2896 | C21: 2024652 | D21: 2033130 | E21: 20240727zes1942 | M21: А там (тама) на гормошке играли, была площадка сделаная из = это по = просто нацгак = как танцплощадка такая | N21: из | O21: дерева, из досок сложена. | P21: дерева | Q21: 0 | R21: 0 | S21: 0 | T21: 0 | U21: 0 | V21: 0 | W21: 0 | X21: 0 | Y21: 1 | Z21: 0 | AA21: 0 | AB21: 0 | AC21: 0 | AD21: a | AE21: n | AF21: y
A22: корпус говора деревни Пятиусово | B22: 2896 | C22: 2024652 | D22: 2033130 | E22: 20240727zes1942 | M22: А там (тама) на гормошке играли, была площадка сделаная из = это по = просто нацгак = как танцплощадка такая из дерева, | N22: из | O22: досок сложена. | P22: досок | Q22: 0 | R22: 0 | S22: 0 | T22: 0 | U22: 0 | V22: 0 | W22: 0 | X22: 0 | Y22: 1 | Z22: 0 | AA22: 0 | AB22: 0 | AC22: 0 | AD22: o | AE22: v | AF22: y
A23: корпус говора деревни Пятиусово | B23: 3133 | C23: 3278776 | D23: 3281644 | E23: 20240727zes1942 | N23: Из | O23: тринадцати деревень оставши вот только вот эта. | P23: деревень | Q23: 0 | R23: 1 | S23: 0 | T23: 0 | U23: 0 | V23: 0 | W23: 0 | X23: 0 | Y23: 0 | Z23: 0 | AA23: 0 | AB23: 0 | AC23: 0 | AD23: o | AE23: n | AF23: y
A24: корпус говора деревни Пятиусово | B24: 3299 | C24: 4384932 | D24: 4391489 | E24: 20240727zes1942 | M24: Де = де = держа = держали. Я держала, даже кто - то | N24: из | O24: ребят из ваших приходил, я давала, помню, сало. | P24: ребят | Q24: 0 | R24: 0 | S24: 0 | T24: 0 | U24: 0 | V24: 0 | W24: 0 | X24: 0 | Y24: 0 | Z24: 0 | AA24: 1 | AB24: 0 | AC24: 0 | AD24: o | AE24: n | AF24: y
A25: корпус говора деревни Пятиусово | B25: 3869 | C25: 1466970 | D25: 1474310 | E25: 20240802zes1942 | M25: Их в совхозе много было, их не оставши почти никого и = и = | N25: из | O25: моих ровесников. У Рыжиковой Любы не были вы? | P25: ровесники | Q25: 0 | R25: 0 | S25: 0 | T25: 0 | U25: 0 | V25: 0 | W25: 0 | X25: 0 | Y25: 0 | Z25: 0 | AA25: 1 | AB25: 0 | AC25: 0 | AD25: a | AE25: n | AF25: y
A26: корпус говора деревни Пятиусово | B26: 3885 | C26: 1498310 | D26: 1501090 | E26: 20240802zes1942 | M26: Да, она родом | N26: из | O26: Каськова, да. | P26: Каськово | Q26: 1 | R26: 0 | S26: 0 | T26: 0 | U26: 0 | V26: 0 | W26: 0 | X26: 0 | Y26: 0 | Z26: 0 | AA26: 0 | AB26: 0 | AC26: 1 | AD26: a | AE26: n | AF26: y
A27: корпус говора деревни Пятиусово | B27: 732 | C27: 2758059 | D27: 2762881 | E27: 20240729evm1937 | G27: EVM1937 | I27: 1937 | J27: техникум | K27: Коковино | L27: Пятиусово | M27: Варежки все вязали шерстяные, из овец = | N27: из | O27: овечей шерсти. | P27: шерсть | Q27: 0 | R27: 0 | S27: 0 | T27: 0 | U27: 0 | V27: 0 | W27: 0 | X27: 0 | Y27: 1 | Z27: 0 | AA27: 0 | AB27: 0 | AC27: 0 | AD27: o | AE27: v | AF27: y
A28: корпус говора деревни Пятиусово | B28: 3869 | C28: 1466970 | D28: 1474310 | E28: 20240802zes1942 | M28: Их в совхозе много было, их не оставши почти никого и = и = | N28: из | O28: моих ровесников. У Рыжиковой Любы не были вы? | P28: ровесник | Q28: 0 | R28: 0 | S28: 0 | T28: 0 | U28: 0 | V28: 0 | W28: 0 | X28: 0 | Y28: 0 | Z28: 0 | AA28: 1 | AB28: 0 | AC28: 0 | AD28: a | AE28: n | AF28: y
A29: корпус говора деревни Пятиусово | B29: 3976 | C29: 1802650 | D29: 1808240 | E29: 20240802zes1942 | M29: Фляги эти в = вых = выносили на улицу. На улице было щит сделано | N29: из | O29: досок. | P29: досок | Q29: 0 | R29: 0 | S29: 0 | T29: 0 | U29: 0 | V29: 0 | W29: 0 | X29: 0 | Y29: 1 | Z29: 0 | AA29: 0 | AB29: 0 | AC29: 0 | AD29: o | AE29: v | AF29: y
A30: корпус говора деревни Пятиусово | B30: 3978 | C30: 1808950 | D30: 1814380 | E30: 20240802zes1942 | M30: И там была сделана яма | N30: из | O30: цемента. Пускали туда воду и ставили фляги туда. | P30: цемента | Q30: 0 | R30: 0 | S30: 0 | T30: 0 | U30: 0 | V30: 0 | W30: 0 | X30: 0 | Y30: 1 | Z30: 0 | AA30: 0 | AB30: 0 | AC30: 0 | AD30: o | AE30: v | AF30: y
A31: корпус говора деревни Пятиусово | B31: 4351 | C31: 3002840 | D31: 3009670 | E31: 20240802zes1942 | M31: В подполье сразу сыпали, а сейчас в подполье не сыпят (сыплют). Сейчас сыпят (сыплют) в сарай или у кого оббито, такие, сделано | N31: из | O31: досок... | P31: досок | Q31: 0 | R31: 0 | S31: 0 | T31: 0 | U31: 0 | V31: 0 | W31: 0 | X31: 0 | Y31: 1 | Z31: 0 | AA31: 0 | AB31: 0 | AC31: 0 | AD31: o | AE31: v | AF31: y
A32: корпус говора деревни Пятиусово | B32: 4371 | C32: 3068330 | D32: 3075760 | E32: 20240802zes1942 | M32: Сделанный | N32: из | O32: фундамента. Там (тама) не у (в) одних у них, на их (ихней) улице, наверное во = кто желал, все делали тогда, она сказала. | P32: фундамента | Q32: 0 | R32: 0 | S32: 0 | T32: 0 | U32: 0 | V32: 0 | W32: 0 | X32: 0 | Y32: 1 | Z32: 0 | AA32: 0 | AB32: 0 | AC32: 0 | AD32: o | AE32: v | AF32: y
A33: корпус говора деревни Пятиусово | B33: 4412 | C33: 3191170 | D33: 3198320 | E33: 20240802zes1942 | M33: И была сделана лежанка | N33: из | O33: дереве = из = из досок, из досок. | P33: дерева | Q33: 0 | R33: 0 | S33: 0 | T33: 0 | U33: 0 | V33: 0 | W33: 0 | X33: 0 | Y33: 1 | Z33: 0 | AA33: 0 | AB33: 0 | AC33: 0 | AD33: o | AE33: v | AF33: y
A34: корпус говора деревни Пятиусово | B34: 4412 | C34: 3191170 | D34: 3198320 | E34: 20240802zes1942 | M34: И была сделана лежанка из дереве = из = | N34: из | O34: досок, из досок. | P34: досок | Q34: 0 | R34: 0 | S34: 0 | T34: 0 | U34: 0 | V34: 0 | W34: 0 | X34: 0 | Y34: 1 | Z34: 0 | AA34: 0 | AB34: 0 | AC34: 0 | AD34: o | AE34: v | AF34: y
A35: корпус говора деревни Пятиусово | B35: 4412 | C35: 3191170 | D35: 3198320 | E35: 20240802zes1942 | M35: И была сделана лежанка из дереве = из = из досок, | N35: из | O35: досок. | P35: досок | Q35: 0 | R35: 0 | S35: 0 | T35: 0 | U35: 0 | V35: 0 | W35: 0 | X35: 0 | Y35: 1 | Z35: 0 | AA35: 0 | AB35: 0 | AC35: 0 | AD35: o | AE35: v | AF35: y
A36: корпус говора деревни Пятиусово | B36: 4784 | C36: 4274800 | D36: 4285570 | E36: 20240802zes1942 | M36: Его делают. Вот руками (рукам) держатся вот так. Ну теперь (теперя) я видела у Бориса Николаевича какой - то вообще на палках, которым там. У нас специально делают | N36: из | O36: брёда такую. | P36: брёда | Q36: 0 | R36: 0 | S36: 0 | T36: 0 | U36: 0 | V36: 0 | W36: 0 | X36: 0 | Y36: 1 | Z36: 0 | AA36: 0 | AB36: 0 | AC36: 0 | AD36: o | AE36: v | AF36: y
A37: корпус говора деревни Пятиусово | B37: 5180 | C37: 739190 | D37: 764381 | E37: 20240804zes1942 | M37: Ну покупаю эти корма, покупаю корма в магазине, ну и иногда если только свежого супа, если | N37: из | O37: куры, курятину и так, если чуть - чуть, а так не особо. Ну рыбу любит, бывало, мойва была. Сейчас мойвы нет, бывала мойва. То супа сварю из мойвы, чтобы покушать, то так, а так он сейчас, он молоко любит, молоко когда дают.. | P37: куры | Q37: 0 | R37: 0 | S37: 0 | T37: 0 | U37: 0 | V37: 0 | W37: 0 | X37: 0 | Y37: 1 | Z37: 0 | AA37: 0 | AB37: 0 | AC37: 0 | AD37: a | AE37: n | AF37: y
A38: корпус говора деревни Пятиусово | B38: 5180 | C38: 739190 | D38: 764381 | E38: 20240804zes1942 | M38: Ну покупаю эти корма, покупаю корма в магазине, ну и иногда если только свежого супа, если из куры, курятину и так, если чуть - чуть, а так не особо. Ну рыбу любит, бывало, мойва была. Сейчас мойвы нет, бывала мойва. То супа сварю | N38: из | O38: мойвы, чтобы покушать, то так, а так он сейчас, он молоко любит, молоко когда дают.. | P38: мойвы | Q38: 0 | R38: 0 | S38: 0 | T38: 0 | U38: 0 | V38: 0 | W38: 0 | X38: 0 | Y38: 1 | Z38: 0 | AA38: 0 | AB38: 0 | AC38: 0 | AD38: o | AE38: v | AF38: y
A39: корпус говора деревни Пятиусово | B39: 5189 | C39: 915667 | D39: 951571 | E39: 20240804zes1942 | N39: Из | O39: молока, которое в хозяйствве, во все времена и даже в пятьдесят восьмом году у нас уже был сепаратор, ещё не замужем была, а нас только приняли в совхоз, совхоз был на деньгах, поэтому нас соединили. И перегоняли, перегон, хочешь на творог перегон, хочешь, держали поросёнка, поросё = поросятам давали и белили, а ну, а молоко, делали масло, творог, ой ели ну такое, своё, ну. | P39: молока | Q39: 0 | R39: 0 | S39: 0 | T39: 0 | U39: 0 | V39: 0 | W39: 0 | X39: 0 | Y39: 1 | Z39: 0 | AA39: 0 | AB39: 0 | AC39: 1 | AD39: o | AE39: v | AF39: y
A40: корпус говора деревни Пятиусово | B40: 5202 | C40: 1384500 | D40: 1402500 | E40: 20240804zes1942 | M40: В Каськове, да, рожала девушка одна молодая, невестка принимала моя роды там, она как бы вызвала скорую там (тама) они, ещё какая - то медичка была, вдвоём принимали роды | N40: из | O40: дома. | P40: дома | Q40: 0 | R40: 0 | S40: 1 | T40: 0 | U40: 0 | V40: 0 | W40: 0 | X40: 0 | Y40: 0 | Z40: 0 | AA40: 0 | AB40: 0 | AC40: 0 | AD40: s | AE40: v | AF40: y
...

Sheet удалено_с
A1: корпус | B1: utterance_id | C1: From | D1: To | E1: File | F1: Id | G1: String id | H1: Gender | I1: Year of birth | J1: Education | K1: Place of birth | L1: Place of living | M1: Left Context | N1: DMatch | O1: Right Context | P1: причина удаления | R1: =IFERROR(__xludf.DUMMYFUNCTION("QUERY(P2:P10000, ""SELECT P, COUNT(P) WHERE P IS NOT NULL AND P != '' GROUP BY P ORDER BY COUNT(P) DESC LABEL COUNT(P) 'Количество'"")"),"") | S1: =IFERROR(__xludf.DUMMYFUNCTION("""COMPUTED_VALUE"""),"Количество") -> Количество
A2: Корпус говора деревни Пятиусово | B2: 55 | C2: 1116181 | D2: 1121630 | E2: 20231028zes1942 | M2: Ну, а мы на улице со ( | N2: с | O2: ) своим дедом, хозяином дрова резали, вот так... | P2: другой падеж | R2: =IFERROR(__xludf.DUMMYFUNCTION("""COMPUTED_VALUE"""),"другой падеж") -> другой падеж | S2: =IFERROR(__xludf.DUMMYFUNCTION("""COMPUTED_VALUE"""),829.0) -> 829
A3: Корпус говора деревни Пятиусово | B3: 62 | C3: 1147370 | D3: 1151750 | E3: 20231028zes1942 | N3: С | O3: неё (ней) не снять это, рукавицы... Варежки раньше были шерстяные. | P3: отсутствует существительное в предложной группе | R3: =IFERROR(__xludf.DUMMYFUNCTION("""COMPUTED_VALUE"""),"нет вариативности") -> нет вариативности | S3: =IFERROR(__xludf.DUMMYFUNCTION("""COMPUTED_VALUE"""),254.0) -> 254
A4: Корпус говора деревни Пятиусово | B4: 77 | C4: 1212489 | D4: 1215709 | E4: 20231028zes1942 | M4: После какой | N4: с | O4: #NAME? | P4: неполные данные | R4: =IFERROR(__xludf.DUMMYFUNCTION("""COMPUTED_VALUE"""),"неполные данные") -> неполные данные | S4: =IFERROR(__xludf.DUMMYFUNCTION("""COMPUTED_VALUE"""),148.0) -> 148
A5: Корпус говора деревни Пятиусово | B5: 91 | C5: 1283884 | D5: 1289084 | E5: 20231028zes1942 | M5: Мы не пускали как - бы... Ночлег, это | N5: с | O5: собой никто не носит, это сейчас у вас машины... | P5: другой падеж | R5: =IFERROR(__xludf.DUMMYFUNCTION("""COMPUTED_VALUE"""),"отсутствует существительное в предложной группе") -> отсутствует существительное в предложной группе | S5: =IFERROR(__xludf.DUMMYFUNCTION("""COMPUTED_VALUE"""),91.0) -> 91
A6: Корпус говора деревни Пятиусово | B6: 113 | C6: 1395162 | D6: 1400395 | E6: 20231028zes1942 | M6: Её называть... Она сама... Я разговаривала | N6: с | O6: ней, тоже, так, когда в автобусе еду... | P6: другой падеж | R6: =IFERROR(__xludf.DUMMYFUNCTION("""COMPUTED_VALUE"""),"временное значение") -> временное значение | S6: =IFERROR(__xludf.DUMMYFUNCTION("""COMPUTED_VALUE"""),33.0) -> 33
A7: Корпус говора деревни Пятиусово | B7: 114 | C7: 1400856 | D7: 1407011 | E7: 20231028zes1942 | M7: Когда в автобусе еду, то люблю поговорить, встретиться | N7: с | O7: кем - то и поговорить... Ну, и спросила у неё (ней)... | P7: другой падеж | R7: =IFERROR(__xludf.DUMMYFUNCTION("""COMPUTED_VALUE"""),"самоповтор") -> самоповтор | S7: =IFERROR(__xludf.DUMMYFUNCTION("""COMPUTED_VALUE"""),26.0) -> 26
A8: Корпус говора деревни Пятиусово | B8: 155 | C8: 1607049 | D8: 1618583 | E8: 20231028zes1942 | M8: На правительство обижаться нельзя, живёт хорошо во главе | N8: с | O8: президентом, живут все хорошо. В нашей деревне, я не знаю, как в других, в нашей все живут хорошо. Кто работал, пенсию заработал, он пенсию... На пенсию живёт. | P8: другой падеж | R8: =IFERROR(__xludf.DUMMYFUNCTION("""COMPUTED_VALUE"""),"идиома/фразеологизм") -> идиома/фразеологизм | S8: =IFERROR(__xludf.DUMMYFUNCTION("""COMPUTED_VALUE"""),22.0) -> 22
A9: Корпус говора деревни Пятиусово | B9: 193 | C9: 1877298 | D9: 1881498 | E9: 20231028zes1942 | M9: Ну и, так вкусны (укусны) были | N9: с | O9: молоком, но держали корову. | P9: другой падеж | R9: =IFERROR(__xludf.DUMMYFUNCTION("""COMPUTED_VALUE"""),"мера/сопоставление") -> мера/сопоставление | S9: =IFERROR(__xludf.DUMMYFUNCTION("""COMPUTED_VALUE"""),6.0) -> 6
A10: Корпус говора деревни Пятиусово | B10: 216 | C10: 2007902 | D10: 2014883 | E10: 20231028zes1942 | M10: Всё было, и хлеб было тогда, и все... Стали кровати все | N10: с | O10: клопами выносить вон, раньше клопов было много. | P10: другой падеж | R10: =IFERROR(__xludf.DUMMYFUNCTION("""COMPUTED_VALUE"""),"мера") -> мера | S10: =IFERROR(__xludf.DUMMYFUNCTION("""COMPUTED_VALUE"""),5.0) -> 5
A11: Корпус говора деревни Пятиусово | B11: 218 | C11: 2020393 | D11: 2027793 | E11: 20231028zes1942 | M11: В субботу до обеда, полный день воскресенье, ну, жизнь совсем уже другоая стала конечно, | N11: с | O11: пятьдесят восьмого года она... | R11: =IFERROR(__xludf.DUMMYFUNCTION("""COMPUTED_VALUE"""),"составной предлог") -> составной предлог | S11: =IFERROR(__xludf.DUMMYFUNCTION("""COMPUTED_VALUE"""),5.0) -> 5
A12: Корпус говора деревни Пятиусово | B12: 219 | C12: 2028059 | D12: 2034483 | E12: 20231028zes1942 | N12: С | O12: двадцатого мая... Взяли в это = эту самую... В совхоз соединили. Но совхоз жил хорошо. | P12: нет вариативности | R12: =IFERROR(__xludf.DUMMYFUNCTION("""COMPUTED_VALUE"""),"мера/приблизительно") -> мера/приблизительно | S12: =IFERROR(__xludf.DUMMYFUNCTION("""COMPUTED_VALUE"""),2.0) -> 2
A13: Корпус говора деревни Пятиусово | B13: 221 | C13: 2041377 | D13: 2047516 | E13: 20231028zes1942 | M13: А я старая, никуда, без зуб теперь уже, | N13: с | O13: пятьдесят лет зубов нет, стерялись все... Растерялись все зубы. | P13: нет вариативности
A14: Корпус говора деревни Пятиусово | B14: 240 | C14: 2195910 | D14: 2202667 | E14: 20231028zes1942 | M14: Это вот... А они как - то были приехадчи, а я на улице была, по - моему... Не, в (у) доме была. А Артём был приехадчи | N14: с | O14: ним. | P14: другой падеж
A15: Корпус говора деревни Пятиусово | B15: 261 | C15: 2274410 | D15: 2278840 | E15: 20231028zes1942 | N15: С | O15: друзьями (друзьям) где - то были на охоте, вот он тоже, тоже на охоте, да, вот этот сын. | P15: другой падеж
A16: Корпус говора деревни Пятиусово | B16: 263 | C16: 2282310 | D16: 2285860 | E16: 20231028zes1942 | N16: С | O16: доски почёта... На доске почёта. Ну, у меня, бывало, свои < нрзб > были. | P16: нет вариативности
A17: Корпус говора деревни Пятиусово | B17: 287 | C17: 338700 | D17: 342270 | E17: 20240729evm1937 | G17: EVM1937 | I17: 1937 | J17: техникум | K17: Коковино | L17: Пятиусово | M17: А вы, наверное, там я плохо | N17: с | O17: вами разговаривал, наверное. | P17: другой падеж
A18: Корпус говора деревни Пятиусово | B18: 290 | C18: 349530 | D18: 349973 | E18: 20240729evm1937 | G18: EVM1937 | I18: 1937 | J18: техникум | K18: Коковино | L18: Пятиусово | M18: Я | N18: с | O18: =... -> #ERROR! | P18: неполные данные
A19: Корпус говора деревни Пятиусово | B19: 299 | C19: 388786 | D19: 392800 | E19: 20240729evm1937 | G19: EVM1937 | I19: 1937 | J19: техникум | K19: Коковино | L19: Пятиусово | N19: С | O19: () шестьдесят второго года. | P19: нет вариативности
A20: Корпус говора деревни Пятиусово | B20: 307 | C20: 427810 | D20: 428990 | E20: 20240729evm1937 | G20: EVM1937 | I20: 1937 | J20: техникум | K20: Коковино | L20: Пятиусово | N20: С | O20: шестьдесят второго года. | P20: нет вариативности
A21: Корпус говора деревни Пятиусово | B21: 324 | C21: 498040 | D21: 502290 | E21: 20240729evm1937 | G21: EVM1937 | I21: 1937 | J21: техникум | K21: Коковино | L21: Пятиусово | M21: Это так у меня лейтенант называл, когда я | N21: с | O21: ним еду в машине. | P21: другой падеж
A22: Корпус говора деревни Пятиусово | B22: 375 | C22: 797525 | D22: 802525 | E22: 20240729evm1937 | G22: EVM1937 | I22: 1937 | J22: техникум | K22: Коковино | L22: Пятиусово | M22: Был на Бакуриани - - три тысячи | N22: с | O22: половиной, тысячи над уровнем моря. | P22: другой падеж
A23: Корпус говора деревни Пятиусово | B23: 376 | C23: 802725 | D23: 813830 | E23: 20240729evm1937 | G23: EVM1937 | I23: 1937 | J23: техникум | K23: Коковино | L23: Пятиусово | M23: Я спускал оттуда станцию, с Бакуриани, | N23: с | O23: тягачом АТС, а сзади приёмо - передающая кабина, 20 тонн. | P23: другой падеж
A24: Корпус говора деревни Пятиусово | B24: 381 | C24: 844250 | D24: 850425 | E24: 20240729evm1937 | G24: EVM1937 | I24: 1937 | J24: техникум | K24: Коковино | L24: Пятиусово | M24: А как посмотришь они | N24: с | O24: такой вроде, панамы поднимаются, волосы кверху, не захочешь смотреть | P24: другой падеж
A25: Корпус говора деревни Пятиусово | B25: 390 | C25: 902287 | D25: 913162 | E25: 20240729evm1937 | G25: EVM1937 | I25: 1937 | J25: техникум | K25: Коковино | L25: Пятиусово | M25: На третьи сутки товарищ у нас один говорит: " Мы пойдем, Муравьёв, | N25: с | O25: тобой на метеостаницию. " | P25: другой падеж
A26: Корпус говора деревни Пятиусово | B26: 399 | C26: 953412 | D26: 955500 | E26: 20240729evm1937 | G26: EVM1937 | I26: 1937 | J26: техникум | K26: Коковино | L26: Пятиусово | M26: И там мы | N26: с | O26: ним (им) пробыли до отбоя. | P26: другой падеж
A27: Корпус говора деревни Пятиусово | B27: 437 | C27: 1155510 | D27: 1165021 | E27: 20240729evm1937 | G27: EVM1937 | I27: 1937 | J27: техникум | K27: Коковино | L27: Пятиусово | M27: И здесь я создал семью, познакомился | N27: с | O27: дамой или с девочкой назовем, дамой (дамом) тогда не называли. | P27: другой падеж
A28: Корпус говора деревни Пятиусово | B28: 437 | C28: 1155510 | D28: 1165021 | E28: 20240729evm1937 | G28: EVM1937 | I28: 1937 | J28: техникум | K28: Коковино | L28: Пятиусово | M28: И здесь я создал семью, познакомился с дамой или | N28: с | O28: девочкой назовем, дамой (дамом) тогда не называли. | P28: другой падеж
A29: Корпус говора деревни Пятиусово | B29: 465 | C29: 1319573 | D29: 1328935 | E29: 20240729evm1937 | G29: EVM1937 | I29: 1937 | J29: техникум | K29: Коковино | L29: Пятиусово | M29: Я говорю: " Ну как я буду работать? Я среднетехнического образования, агрономы | N29: с | O29: высшим, приду, зоотехники с высшим, мне как - то неудобно. " | P29: другой падеж
A30: Корпус говора деревни Пятиусово | B30: 465 | C30: 1319573 | D30: 1328935 | E30: 20240729evm1937 | G30: EVM1937 | I30: 1937 | J30: техникум | K30: Коковино | L30: Пятиусово | M30: Я говорю: " Ну как я буду работать? Я среднетехнического образования, агрономы с высшим, приду, зоотехники | N30: с | O30: высшим, мне как - то неудобно. " | P30: другой падеж
A31: Корпус говора деревни Пятиусово | B31: 480 | C31: 1425550 | D31: 1440820 | E31: 20240729evm1937 | G31: EVM1937 | I31: 1937 | J31: техникум | K31: Коковино | L31: Пятиусово | M31: Она тяжело болела, не так что тяжело, но болела, пользовалась ингалятором, у неё плохо | N31: с | O31: сердцем было, с дыханием, ушла из жизни. | P31: другой падеж
A32: Корпус говора деревни Пятиусово | B32: 480 | C32: 1425550 | D32: 1440820 | E32: 20240729evm1937 | G32: EVM1937 | I32: 1937 | J32: техникум | K32: Коковино | L32: Пятиусово | M32: Она тяжело болела, не так что тяжело, но болела, пользовалась ингалятором, у неё плохо с сердцем было, | N32: с | O32: дыханием, ушла из жизни. | P32: другой падеж
... A66: Корпус говора деревни Пятиусово | B66: 1113 | C66: 1209120 | D66: 1217220 | E66: 20231026lng1954 | G66: LNG1954 | I66: 1954 | J66: среднее (10 классов) | K66: Пятиусово | L66: Пятиусово | M66: А краски не было, а ехать в городо, туда в (у) Западную, | N66: с | O66: большим количеством - объёмом краски, а у меня (мне) было вот такой... | P66: другой падеж
A67: Корпус говора деревни Пятиусово | B67: 1122 | C67: 1274400 | D67: 1293080 | E67: 20231026lng1954 | G67: LNG1954 | I67: 1954 | J67: среднее (10 классов) | K67: Пятиусово | L67: Пятиусово | M67: Ну в современном (совремённом) Красногорске. | N67: С | O67: =по - моему, сорок три или сорок восемь квадратов там, раздельно что. Вот дочка на выданье будет, куда, чего, что. А потом раз у человека на генетическом уровне забит это, они же вот эта ностальгия, деревенские они всё равно, к земле их тянет, вот. -> #ERROR! | P67: неполные данные
A68: Корпус говора деревни Пятиусово | B68: 1136 | C68: 1387020 | D68: 1396786 | E68: 20231026lng1954 | G68: LNG1954 | I68: 1954 | J68: среднее (10 классов) | K68: Пятиусово | L68: Пятиусово | M68: Без.. Короче, я на Новый год бросил работать, а | N68: с | O68: двадцатого февраля девяностого года я там служил. И вот начальником караула, в охране был. | P68: нет вариативности
A69: Корпус говора деревни Пятиусово | B69: 1139 | C69: 1404866 | D69: 1412720 | E69: 20231026lng1954 | G69: LNG1954 | I69: 1954 | J69: среднее (10 классов) | K69: Пятиусово | L69: Пятиусово | M69: Это | N69: с | O69: тридцать третьего года организовано. Это ну Кубышка, это государственное, допустим, на случай войны что - то, такое это вот это. | P69: нет вариативности
A70: Корпус говора деревни Пятиусово | B70: 1142 | C70: 1422079 | D70: 1428866 | E70: 20231026lng1954 | G70: LNG1954 | I70: 1954 | J70: среднее (10 классов) | K70: Пятиусово | L70: Пятиусово | M70: Сейчас я уже не знаю. Информация я обладаю ту, которую в мою бытость это было - - я | N70: с | O70: четырнадцатого года на пенсии. | P70: нет вариативности
A71: Корпус говора деревни Пятиусово | B71: 1146 | C71: 1446293 | D71: 1456266 | E71: 20231026lng1954 | G71: LNG1954 | I71: 1954 | J71: среднее (10 классов) | K71: Пятиусово | L71: Пятиусово | M71: А начинал вот тут в совхозе, вот. До судимости я трактористом работал на тракторе. Ну там я мало, это | N71: с | O71: семьдесят первого года с октября по апрель. | P71: нет вариативности
A72: Корпус говора деревни Пятиусово | B72: 1146 | C72: 1446293 | D72: 1456266 | E72: 20231026lng1954 | G72: LNG1954 | I72: 1954 | J72: среднее (10 классов) | K72: Пятиусово | L72: Пятиусово | M72: А начинал вот тут в совхозе, вот. До судимости я трактористом работал на тракторе. Ну там я мало, это с семьдесят первого года | N72: с | O72: октября по апрель. | P72: нет вариативности
A73: Корпус говора деревни Пятиусово | B73: 1160 | C73: 1540706 | D73: 1546773 | E73: 20231026lng1954 | G73: LNG1954 | I73: 1954 | J73: среднее (10 классов) | K73: Пятиусово | L73: Пятиусово | M73: Вот пять месяцев я закончил школу и поступил | N73: с | O73: нового года сюда, шофёром работал. | P73: нет вариативности
...

Sheet удалено_из
A1: Корпус | B1: utterance_id | C1: From | D1: To | E1: File | F1: Id | G1: String id | H1: Gender | I1: Year of birth | J1: Education | K1: Place of birth | L1: Place of living | M1: Left Context | N1: DMatch | O1: Right Context | P1: причина удаления | S1: =IFERROR(__xludf.DUMMYFUNCTION("QUERY(P2:P10000, ""SELECT P, COUNT(P) WHERE P IS NOT NULL AND P != '' GROUP BY P ORDER BY COUNT(P) DESC LABEL COUNT(P) 'Количество'"")"),"") | T1: =IFERROR(__xludf.DUMMYFUNCTION("""COMPUTED_VALUE"""),"Количество") -> Количество
A2: Корпус говора деревни Пятиусово | B2: 150 | C2: 1585412 | D2: 1589895 | E2: 20231028zes1942 | M2: А они, бывало, тихонечко | N2: из | O2: - под (спод) парты пряничек, конфетку... | P2: составной предлог | S2: =IFERROR(__xludf.DUMMYFUNCTION("""COMPUTED_VALUE"""),"составной предлог") -> составной предлог | T2: =IFERROR(__xludf.DUMMYFUNCTION("""COMPUTED_VALUE"""),13.0) -> 13
A3: Корпус говора деревни Пятиусово | B3: 264 | C3: 2286430 | D3: 2294940 | E3: 20231028zes1942 | M3: Вот... На = на вид красива =, ну она - то худая, а мне было двадцать девять лет тут (тута), я была всё время зудая, это сейчас я разъелась | N3: из | O3: ... Разъелась как корова... | P3: неполные данные | S3: =IFERROR(__xludf.DUMMYFUNCTION("""COMPUTED_VALUE"""),"неполные данные") -> неполные данные | T3: =IFERROR(__xludf.DUMMYFUNCTION("""COMPUTED_VALUE"""),8.0) -> 8
A4: Корпус говора деревни Пятиусово | B4: 479 | C4: 1413700 | D4: 1423570 | E4: 20240729evm1937 | G4: EVM1937 | I4: 1937 | J4: техникум | K4: Коковино | L4: Пятиусово | M4: Первая жена умерла, где - то двадцать пять лет уже, как ушла | N4: из | O4: жизни. | P4: идиома/фразеологизм | S4: =IFERROR(__xludf.DUMMYFUNCTION("""COMPUTED_VALUE"""),"вопрос интервьюера") -> вопрос интервьюера | T4: =IFERROR(__xludf.DUMMYFUNCTION("""COMPUTED_VALUE"""),6.0) -> 6
A5: Корпус говора деревни Пятиусово | B5: 480 | C5: 1425550 | D5: 1440820 | E5: 20240729evm1937 | G5: EVM1937 | I5: 1937 | J5: техникум | K5: Коковино | L5: Пятиусово | M5: Она тяжело болела, не так что тяжело, но болела, пользовалась ингалятором, у неё плохо с сердцем было, с дыханием, ушла | N5: из | O5: жизни. | P5: идиома/фразеологизм | S5: =IFERROR(__xludf.DUMMYFUNCTION("""COMPUTED_VALUE"""),"отсутствие существительного в предложной группе") -> отсутствие существительного в предложной группе | T5: =IFERROR(__xludf.DUMMYFUNCTION("""COMPUTED_VALUE"""),5.0) -> 5
A6: Корпус говора деревни Пятиусово | B6: 482 | C6: 1449000 | D6: 1457420 | E6: 20240729evm1937 | G6: EVM1937 | I6: 1937 | J6: техникум | K6: Коковино | L6: Пятиусово | M6: Тоже с сердцем, два или три, инфаркт или инсульт, ушла | N6: из | O6: жизни. | P6: идиома/фразеологизм | S6: =IFERROR(__xludf.DUMMYFUNCTION("""COMPUTED_VALUE"""),"самоповтор") -> самоповтор | T6: =IFERROR(__xludf.DUMMYFUNCTION("""COMPUTED_VALUE"""),5.0) -> 5
A7: Корпус говора деревни Пятиусово | B7: 973 | C7: 359492 | D7: 366199 | E7: 20231026lng1954 | G7: LNG1954 | I7: 1954 | J7: среднее (10 классов) | K7: Пятиусово | L7: Пятиусово | M7: Дальше - - больше. Там уже такие проблемы, знаешь, | N7: из | O7: - за пустяка может это всё. | P7: составной предлог | S7: =IFERROR(__xludf.DUMMYFUNCTION("""COMPUTED_VALUE"""),"идиома/фразеологизм") -> идиома/фразеологизм | T7: =IFERROR(__xludf.DUMMYFUNCTION("""COMPUTED_VALUE"""),4.0) -> 4
A8: Корпус говора деревни Пятиусово | B8: 988 | C8: 447600 | D8: 459493 | E8: 20231026lng1954 | G8: LNG1954 | I8: 1954 | J8: среднее (10 классов) | K8: Пятиусово | L8: Пятиусово | M8: И разругались, понимаешь? Вот | N8: из | O8: - за чего разругались? Ещё и как говорят... Да, и билета нету, а они вот деньги деливши разругались. Понимаешь? Так вот жизнь устроен. | P8: составной предлог | S8: =IFERROR(__xludf.DUMMYFUNCTION("""COMPUTED_VALUE"""),"Предлог с") -> Предлог с | T8: =IFERROR(__xludf.DUMMYFUNCTION("""COMPUTED_VALUE"""),3.0) -> 3
A9: Корпус говора деревни Пятиусово | B9: 1055 | C9: 870426 | D9: 874039 | E9: 20231026lng1954 | G9: LNG1954 | I9: 1954 | J9: среднее (10 классов) | K9: Пятиусово | L9: Пятиусово | M9: И вот я семь лет от звонка до звонка отсидел, вот. | N9: Из | O9: неё... | P9: отсутствие существительного в предложной группе | S9: =IFERROR(__xludf.DUMMYFUNCTION("""COMPUTED_VALUE"""),"отсутствие лексически выраженного существительного") -> отсутствие лексически выраженного существительного | T9: =IFERROR(__xludf.DUMMYFUNCTION("""COMPUTED_VALUE"""),3.0) -> 3
A10: Корпус говора деревни Пятиусово | B10: 2134 | C10: 3052780 | D10: 3054740 | E10: 20240728zes1942 | M10: Они теперь ушли уже | N10: из | O10: жизни. | P10: идиома/фразеологизм | S10: =IFERROR(__xludf.DUMMYFUNCTION("""COMPUTED_VALUE"""),"временное значение") -> временное значение | T10: =IFERROR(__xludf.DUMMYFUNCTION("""COMPUTED_VALUE"""),2.0) -> 2
A11: Корпус говора деревни Пятиусово | B11: 2377 | C11: 4090069 | D11: 4093879 | E11: 20240728zes1942 | M11: И они вот переехали | N11: из | O11: #NAME? | P11: неполные данные | S11: =IFERROR(__xludf.DUMMYFUNCTION("""COMPUTED_VALUE"""),"идиомы/фразеологизмы") -> идиомы/фразеологизмы | T11: =IFERROR(__xludf.DUMMYFUNCTION("""COMPUTED_VALUE"""),2.0) -> 2
A12: Корпус говора деревни Пятиусово | B12: 2377 | C12: 4090069 | D12: 4093879 | E12: 20240728zes1942 | M12: И они вот переехали из = из этих домов в один | N12: из | O12: них. | P12: отсутствие существительного в предложной группе | S12: =IFERROR(__xludf.DUMMYFUNCTION("""COMPUTED_VALUE"""),"неподходяший контекст") -> неподходяший контекст | T12: =IFERROR(__xludf.DUMMYFUNCTION("""COMPUTED_VALUE"""),2.0) -> 2
A13: Корпус говора деревни Пятиусово | B13: 2896 | C13: 2024652 | D13: 2033130 | E13: 20240727zes1942 | M13: А там (тама) на гормошке играли, была площадка сделаная | N13: из | O13: =это по = просто нацгак = как танцплощадка такая из дерева, из досок сложена. -> #ERROR! | P13: неполные данные | S13: =IFERROR(__xludf.DUMMYFUNCTION("""COMPUTED_VALUE"""),"колодец") -> колодец | T13: =IFERROR(__xludf.DUMMYFUNCTION("""COMPUTED_VALUE"""),1.0) -> 1
A14: Корпус говора деревни Пятиусово | B14: 3299 | C14: 4384932 | D14: 4391489 | E14: 20240727zes1942 | M14: Де = де = держа = держали. Я держала, даже кто - то из ребят | N14: из | O14: ваших приходил, я давала, помню, сало. | P14: отсутствие существительного в предложной группе | S14: =IFERROR(__xludf.DUMMYFUNCTION("""COMPUTED_VALUE"""),"повтор") -> повтор | T14: =IFERROR(__xludf.DUMMYFUNCTION("""COMPUTED_VALUE"""),1.0) -> 1
A15: Корпус говора деревни Пятиусово | B15: 3682 | C15: 870030 | D15: 872770 | E15: 20240802zes1942 | M15: А она с = ваша родная? | N15: Из | O15: Спиридово тоже? | P15: вопрос интервьюера | S15: =IFERROR(__xludf.DUMMYFUNCTION("""COMPUTED_VALUE"""),"предлог с") -> предлог с | T15: =IFERROR(__xludf.DUMMYFUNCTION("""COMPUTED_VALUE"""),1.0) -> 1
A16: Корпус говора деревни Пятиусово | B16: 3717 | C16: 997840 | D16: 1004450 | E16: 20240802zes1942 | M16: И она в одном | N16: из | O16: , в двухквартирном доме жила в одной стороне (стороны) она жила, во второй другие соседи жили. Потом... | P16: неполные данные | S16: =IFERROR(__xludf.DUMMYFUNCTION("""COMPUTED_VALUE"""),"предлог со") -> предлог со | T16: =IFERROR(__xludf.DUMMYFUNCTION("""COMPUTED_VALUE"""),1.0) -> 1
A17: Корпус говора деревни Пятиусово | B17: 3796 | C17: 1243670 | D17: 1248490 | E17: 20240802zes1942 | M17: А все ваши бабушки, дедушки, они тоже | N17: из | O17: Спиридово? Или ещё откуда - то отсюда? | P17: вопрос интервьюера
A18: Корпус говора деревни Пятиусово | B18: 3884 | C18: 1496215 | D18: 1498285 | E18: 20240802zes1942 | M18: Она тоже | N18: из | O18: Каськ =. Она говорит, что она из Каськова. | P18: самоповтор
A19: Корпус говора деревни Пятиусово | B19: 4408 | C19: 3175420 | D19: 3184220 | E19: 20240802zes1942 | M19: И у нас печа была большая. Я даже не знаю | N19: из | O19: (с) чего она. Мать сказала, из (с) камней, вроде, сделана была эта. Она сделана ещё до = до войны. | P19: отсутствие существительного в предложной группе
A20: Корпус говора деревни Пятиусово | B20: 4411 | C20: 3186850 | D20: 3190630 | E20: 20240802zes1942 | M20: Она... С = | N20: из | O20: (с) камней делали. Она большая была тоже. | P20: предлог с
A21: Корпус говора деревни Пятиусово | B21: 4412 | C21: 3191170 | D21: 3198320 | E21: 20240802zes1942 | M21: И была сделана лежанка из дереве = | N21: из | O21: =из досок, из досок. -> #ERROR! | P21: самоповтор
A22: Корпус говора деревни Пятиусово | B22: 5080 | C22: 5080620 | D22: 5082920 | E22: 20240802zes1942 | M22: Скажите, а вы сами когда - нибудь | N22: из | O22: деревни уезжали? | P22: вопрос интервьюера
A23: Корпус говора деревни Пятиусово | B23: 5116 | C23: 5174460 | D23: 5176500 | E23: 20240802zes1942 | M23: А в Луки автобус ходит | N23: из | O23: Торопы? | P23: вопрос интервьюера
A24: Корпус говора деревни Пятиусово | B24: 5254 | C24: 1988900 | D24: 2130100 | E24: 20240804zes1942 | M24: В де = в детстве какие вам истории надо, я вам расскажу историю, могу рассказать одну, у нас же дружили, ну я думаю, может кто и рассказывал вам из деревни. Дружил парень с девушкой, уже хотели жениться, ну это это на самом деле такое есть, было, и они, значит, на =, свадьба назначена, точно не могу, по - моему, как на Троицу. Они за два дня Троицы пошли в этом, говорит (говорить) мужик её (еёный), теперь ну парень, назовём его. Говорит (говорить), пойдём искупаемся, пошли к речке купаться напротив кладбища где - то туда, он как разделся, как нырнул, так и не вынырнул, вот такой случай это вот был. И вот она осталась на берегу, и потом она вышла за другого замуж, она сама позже умерла (умёрши), ну а дети в Ленинграде, одна дочка вроде умерла (умерши) уже. Так вот такой сулчай был, но | N24: из | O24: ма = из материного рассказа, ну она рассказывала, что - то, она сказала < нрзб > значит (значить), правильнро как сказать, сейчас скажу. Ну как бы в жизни всяко бывает, и не складывается жизнь. Ну приходит дочка к матери и говорит, говорит (говорить), я не хочу жить, я ну что там (тама) не ладится жизнь то ли < нрзб >, но я не спрашивала, точно не могу сказать, она ей говорит, знаешь, детка, дочь, говорит, вот, если тебе накакают на голову, ты скинь с головы, извините за выражение, и опять живи. Ну что, то это жизнь, говорит, не что - нибудь, вот такое. Ну и потом рассказывала, мужик, значит, ходит к женщине ходит (ходить) и ходит (ходить), она, значит, как лето приходит, так ему надо спать на сеновале, но эта жёнка, она понимает что - то, что да нет, она раз послушала, два послушала людей, говорит, надо мне пос = самой покараулить. Она пошла караулить, караулит (караулить), значит, они полезли на черда = на = на = на хлё = на сарай. Она помокнула в жижу, раньше жижесборники такие за хлёвом были, метлу, и туда на это самое, на хлёв их метлой этой с жижей. Говорит (говорить), вот такой случай был. Но драться никто не дрался, она сказала, не дрались, а вот такой случай был. | P24: самоповтор
A25: Корпус говора деревни Пятиусово | B25: 5271 | C25: 3091200 | D25: 3164300 | E25: 20240804zes1942 | M25: А так ну мно = много помню, всё | N25: из | O25: детства, я думаю, с трёх годов, с трёх лет я чу всё на свете помню, с трёх, если не раньше. Всё ка = как раньше же не было это самое во время войны мне было в сорок пятом году три года было < нрзб > четвёртый шёл, и ну я думаю, это года два мои, я думаю, мне года два было, и тогда был год ну чего - то такой голодный год был совсем, и вот я не помню только сейчас, не могу ск =, лошади то ли умерли (умёрши были) и к = погибали, наверное, и знаю, что бабушка принесла или кто - то принёс ей, она варила это мясо в печке, печи были, печи, в чугунке, чугунки были, в чугунке варила мясо, это потом с чугунка вытянула, и стол и дом тот сейчас стоит старый, поставила на стол, вытянула она такие лавки раньше были, ничего не было, одни скамейки были. Ну и она разложила меленько, она мясо такое длинное, помню это, она меленько разрезала, вот ешь потихонечку, это помню хорошо. | P25: временное значение
A26: Корпус говора деревни Пятиусово | B26: 5688 | C26: 2918110 | D26: 2923440 | E26: 20231023vpm1934_1 | G26: VPM1934 | I26: 1934 | J26: техникум | K26: Ануфриево | L26: Пятиусово | M26: Банку колотишь - колотишь - колотишь ну или кто - то | N26: из | O26: м = з = моих кто - то здесь, вот. | P26: неполные данные
A27: Корпус говора деревни Пятиусово | B27: 1729 | C27: 93015 | D27: 94385 | E27: 20180621_avv1933 | I27: 1933 | K27: неоконченное начальное | L27: авв1933 | M27: Ну а что ж | N27: из | O27: детства? | P27: временное значение
A28: Корпус говора деревни Пятиусово | B28: 3884 | C28: 1496215 | D28: 1498285 | E28: 20240802zes1942 | M28: Она тоже из Каськ =. Она говорит, что она | N28: из | O28: Каськова. | P28: вопрос интервьюера
A29: Корпус говора деревни Пятиусово | B29: 4056 | C29: 2095080 | D29: 2096330 | E29: 20240802zes1942 | M29: Аня | N29: из | O29: Горькова. | P29: вопрос интервьюера
A30: Корпус говора деревни Пятиусово | B30: 4462 | C30: 3379720 | D30: 3381540 | E30: 20240802zes1942 | M30: Ну у нас | N30: из | O30: колодца насос. | P30: колодец
A31: Корпус говора деревень Шетнево и Макеево | B31: 678 | C31: 478270 | D31: 481720 | E31: 20210716mga1932 | G31: mga1932 | H31: f | I31: 1932 | J31: начальное | K31: Пожоги | L31: Шетнево | M31: К нам тоже сколько раз приходили < | N31: из | O31: =-за>папки. -> #NAME? | P31: составной предлог
A32: Корпус говора деревень Шетнево и Макеево | B32: 1540 | C32: 574165 | D32: 584544 | E32: 20220715gip1953 | G32: gip1953 | H32: f | I32: 1953 | J32: среднее | K32: Макеево | L32: Макеево | M32: Зимой факел. Делали. Факел | N32: из | O32: такая... Негожая одежда. Её так... В комок делали, связывали. Потом на проволочину, или на палку. | P32: неполные данные
